Workbook

Sheet MARE MX
G1: F | U1: =COUNTA(B3:B561) -> 488 | V1: =SUM(V3:V561) -> 147639.6 | W1: =SUM(W3:W561) -> 152066.18 | X1: =SUM(X3:X561) -> 161268.61 | Y1: =SUM(Y3:Y561) -> 165755.69 | Z1: =SUM(Z3:Z561) -> 170217.87 | AA1: =SUM(AA3:AA561) -> 190347.44 | AB1: =SUM(AB3:AB561) -> 182605.61 | AC1: =SUM(AC3:AC561) -> 184136.46 | AD1: =SUM(AD3:AD561) -> 175678.97 | AT1: =COUNTIF(AT$3:AT$555,"*OK*") -> 5 | AU1: =COUNTIF(AU$3:AU$555,"*OK*") -> 1 | AV1: =COUNTIF(AV$3:AV$555,"*OK*") -> 28 | AW1: =COUNTIF(AW$3:AW$555,"*OK*") -> 5 | AX1: =COUNTIF(AX$3:AX$555,"*OK*") -> 13 | AY1: =COUNTIF(AY$3:AY$555,"*OK*") -> 7 | AZ1: =COUNTIF(AZ$3:AZ$555,"*OK*") -> 11 | BA1: =COUNTIF(BA$3:BA$555,"*OK*") -> 2 | ... BI1: =COUNTIF(BI$3:BI$555,"*OK*") -> 2
A2: ID Geo | B2: RFC | C2: Facturación actual USD | D2: Cross | E2: KAM | F2: CLIENTE | G2: Grupo | H2: Facturación Total | I2: Cartera | J2: Facturado por partner | K2: Enganche otro | L2: Zoho | M2: Cuadrante (MARE + Retener) | N2: Comentario | O2: Nombre | P2: Teléfono | Q2: Correo | R2: GeoCoffee | S2: Tag | T2: Implementando? | U2: Rubro zoho | V2: Enero | W2: Febrero | X2: Marzo | Y2: Abril | Z2: Mayo | AA2: Junio | AB2: Julio | AC2: Agosto | AD2: Septiembre | AE2: Usuarios activos | AF2: Usuarios potenciales (Claude) | AH2: Estado | AI2: Estado Claude | AJ2: Rubro Claude | AK2: Descripción breve de la empresa y a que se dedica | AL2: Rubro | AM2: Primera factura | AN2: Escala comunicación | AO2: Periodicidad | AP2: Operación actual cliente con GV | AQ2: Acción especifica | AR2: Sistema de Nómina | AS2: Nos usa para pagar nómina? | AT2: Alertas | AU2: Integración (VC) | AV2: Permisos y vacaciones | AW2: Planif. Inteligente | AX2: BI | AY2: RAM | AZ2: Acceso | BA2: Comedor | BB2: VictorIA | BC2: Optimizador Turnos | BD2: Marcaje WPP | BE2: WF Cambio de turno | BF2: Plan Pro | BG2: Plan Enterprise | BH2: Formularios | BI2: Upselling | BJ2: Suma Ops | BK2: Arrienda equipos? | BL2: Puntaje Cross | BM2: Riesgo | BN2: Referido/Referencia | BO2: MEDIO DE GESTIÓN | BP2: Orden | BQ2: MEDIO DE CONTACTO | CL2: # Productos OK | CN2: # Productos OP
A3: 29157-37879-36085-37826-36099-38471 | B3: CCO210827216 | C3: =AD3 -> 5979.3046 | D3: 1 | E3: Dafne de la Rosa | F3: J&T EXPRESS CONEJO CORRIENDO | G3: CONEJO CORRIENDO | H3: =IF(LEN(TRIM($G3&""))=0, $C3, SUMIF($G$3:$G$561, TRIM($G3), $C$3:$C$561)) -> 0 | I3: ENTERPRISE | L3: =HYPERLINK("https://crm.zoho.com/crm/org685875245/tab/Accounts/3525045000260992026","https://crm.zoho.com/crm/org685875245/tab/Accounts/3525045000260992026") -> https://crm.zoho.com/crm/org685875245/tab/Accounts/3525045000260992026 | M3: Expandir | O3: Angel | P3: 5615572088 | Q3: angel.olvera@jtexpress.mx | R3: Invitado | U3: - | V3: 2440.36 | W3: 3186.1 | X3: 4304.34 | Y3: 4411.64 | Z3: 4070.0878 | AA3: 5804.78 | AB3: 5002.2185 | AC3: 5772.7131 | AD3: 5979.3046 | AE3: 3582 | AF3: 1355 | AH3: CDMX | AI3: CDMX | AJ3: Logística | AK3: Empresa de mensajería y logística de última milla, parte del grupo internacional J&T Express, con operaciones en toda la República Mexicana. | AL3: Logistica | AR3: Sicoss | AS3: SI | BJ3: =COUNTIF(AT3:BI3,"*OP*") -> 0 | BK3: NO | BL3: =(COUNTIF(AT3:AV3,"*OK*")*3) + (COUNTIF(AW3:AY3,"*OK*")*2) + COUNTIF(AZ3:BB3,"*OK*")+COUNTIF(BK3:BK3,"SI")*0.5 -> 0 | BM3: =IF(BL3<0.6,"Demasiado Riesgo",IF(BL3<=5,"Riesgo Medio",IF(BL3<=11,"Riesgo Bajo","Cliente Blindado"))) -> Demasiado Riesgo | BO3: CON 7 REGIONES CORREO DAFN | BP3: 0 | BQ3: Correo y Llamada | CL3: =COUNTIF(AT3:BH3,"*OK*") -> 0 | CN3: =COUNTIF(AT3:BH3,"*OP*") -> 0
A4: 24596 | B4: SPI180316RR7 | C4: =AD4 -> 5311.2583 | D4: =COUNTIF(AT4:BH4,"*OK*") -> 0 | E4: Raúl Campos | F4: SYD PROYECTOS INTEGRALES (Antromex) | G4: ANTROMEX | H4: =IF(LEN(TRIM($G4&""))=0, $C4, SUMIF($G$3:$G$561, TRIM($G4), $C$3:$C$561)) -> 5311.2583 | I4: ENTERPRISE | L4: =HYPERLINK("https://crm.zoho.com/crm/org685875245/tab/Accounts/3525045000297139312","https://crm.zoho.com/crm/org685875245/tab/Accounts/3525045000297139312") -> https://crm.zoho.com/crm/org685875245/tab/Accounts/3525045000297139312 | M4: Mantener | O4: Marlen Serafin Marlen Serafin | P4: +523112565488 | Q4: rhantromexgdl@gmail.com | U4: - | V4: 4855.91 | W4: 5513.91 | X4: 5601.06 | Y4: 5689.01 | Z4: 5229.4379 | AA4: 5285.23 | AB4: 5332.1193 | AC4: 5485.3039 | AD4: 5311.2583 | AE4: 4909 | AF4: 120 | AI4: Jalisco | AJ4: Construcción | AK4: Empresa constructora con sede en Zapopan, Jalisco, especializada en proyectos integrales de construcción e infraestructura para clientes industriales y corporativos. | AN4: 2. Videollamada | AO4: Semanal | BJ4: =COUNTIF(AT4:BI4,"*OP*") -> 0 | BL4: =(COUNTIF(AT4:AV4,"*OK*")*3) + (COUNTIF(AW4:AY4,"*OK*")*2) + COUNTIF(AZ4:BB4,"*OK*")+COUNTIF(BK4:BK4,"SI")*0.5 -> 0 | BM4: =IF(BL4<0.6,"Demasiado Riesgo",IF(BL4<=5,"Riesgo Medio",IF(BL4<=11,"Riesgo Bajo","Cliente Blindado"))) -> Demasiado Riesgo | BP4: 0 | CL4: =COUNTIF(AT4:BH4,"*OK*") -> 0 | CN4: =COUNTIF(AT4:BH4,"*OP*") -> 0
A5: 7126 | B5: SIR110727BB4 | C5: =AD5 -> 4026.7108 | D5: =COUNTIF(AT5:BH5,"*OK*") -> 0 | E5: Raúl Campos | F5: SERVICIOS INTEGRALES RAMPER(SIRAMPER) | H5: =IF(LEN(TRIM($G5&""))=0, $C5, SUMIF($G$3:$G$561, TRIM($G5), $C$3:$C$561)) -> 4026.7108 | I5: ENTERPRISE | L5: =HYPERLINK("https://crm.zoho.com/crm/org685875245/tab/Accounts/3525045000108826075","https://crm.zoho.com/crm/org685875245/tab/Accounts/3525045000108826075") -> https://crm.zoho.com/crm/org685875245/tab/Accounts/3525045000108826075 | M5: Expandir | O5: Sandy | P5: 5212231138687 | Q5: lopez3664@gmail.com | R5: No están en CDMX | U5: - | V5: 4214.41 | W5: 3964.51 | X5: 3887.79 | Y5: 4227.64 | Z5: 4237.0509 | AA5: 4182.77 | AB5: 4869.1067 | AC5: 4990.7675 | AD5: 4026.7108 | AE5: 1065 | AF5: 600 | AI5: Puebla | AJ5: Outsourcing | AK5: Empresa de outsourcing de servicios de limpieza industrial, conserjería, jardinería y control de plagas, con presencia en 12 estados de México. | AN5: 2. Videollamada | AO5: Semanal | AR5: Contpaqi | BJ5: =COUNTIF(AT5:BI5,"*OP*") -> 0 | BL5: =(COUNTIF(AT5:AV5,"*OK*")*3) + (COUNTIF(AW5:AY5,"*OK*")*2) + COUNTIF(AZ5:BB5,"*OK*")+COUNTIF(BK5:BK5,"SI")*0.5 -> 0 | BM5: =IF(BL5<0.6,"Demasiado Riesgo",IF(BL5<=5,"Riesgo Medio",IF(BL5<=11,"Riesgo Bajo","Cliente Blindado"))) -> Demasiado Riesgo | BP5: 0 | CL5: =COUNTIF(AT5:BH5,"*OK*") -> 0 | CN5: =COUNTIF(AT5:BH5,"*OP*") -> 0
A6: 38530 | B6: DLO1006168N3 | C6: =AD6 -> 4522.0701 | D6: =COUNTIF(AX6:BI6,"OK") -> 0 | E6: Dafne de la Rosa | F6: DICKA LOGISTICS | H6: =IF(LEN(TRIM($G6&""))=0, $C6, SUMIF($G$3:$G$561, TRIM($G6), $C$3:$C$561)) -> 4522.0701 | I6: ENTERPRISE | L6: =HYPERLINK("https://crm.zoho.com/crm/org685875245/tab/Accounts/3525045000545668197","https://crm.zoho.com/crm/org685875245/tab/Accounts/3525045000545668197") -> https://crm.zoho.com/crm/org685875245/tab/Accounts/3525045000545668197 | T6: SI | AA6: 4030.2629 | AB6: 3626.841 | AC6: 4797.4035 | AD6: 4522.0701 | BJ6: =COUNTIF(AT6:BI6,"*OP*") -> 0 | BL6: =(COUNTIF(AT6:AV6,"*OK*")*3) + (COUNTIF(AW6:AY6,"*OK*")*2) + COUNTIF(AZ6:BB6,"*OK*")+COUNTIF(BK6:BK6,"SI")*0.5 -> 0 | BM6: =IF(BL6<0.6,"Demasiado Riesgo",IF(BL6<=5,"Riesgo Medio",IF(BL6<=11,"Riesgo Bajo","Cliente Blindado"))) -> Demasiado Riesgo | CL6: =COUNTIF(AT6:BH6,"*OK*") -> 0
B7: TEK240710P99 | C7: =AD7 -> 4041.9426 | D7: =COUNTIF(AT7:BH7,"*OK*") -> 0 | E7: Raúl Campos | F7: TECNO ESPECIALIZADOS KIURT | H7: =IF(LEN(TRIM($G7&""))=0, $C7, SUMIF($G$3:$G$561, TRIM($G7), $C$3:$C$561)) -> 4041.9426 | I7: ENTERPRISE | J7: TECNO ESPECIALIZADOS KIURT | U7: - | V7: 2852.64 | W7: 2862.77 | X7: 2889.44 | Y7: 3071.38 | Z7: 3295.2622 | AA7: 3510.54 | AC7: 3977.2561 | AD7: 4041.9426 | AF7: 200 | AI7: CDMX | AJ7: Tecnología | AK7: Empresa de tecnología y servicios especializados en soluciones de control de acceso y asistencia, opera como partner de implementación tecnológica. | BJ7: =COUNTIF(AT7:BI7,"*OP*") -> 0 | BL7: =(COUNTIF(AT7:AV7,"*OK*")*3) + (COUNTIF(AW7:AY7,"*OK*")*2) + COUNTIF(AZ7:BB7,"*OK*")+COUNTIF(BK7:BK7,"SI")*0.5 -> 0 | BM7: =IF(BL7<0.6,"Demasiado Riesgo",IF(BL7<=5,"Riesgo Medio",IF(BL7<=11,"Riesgo Bajo","Cliente Blindado"))) -> Demasiado Riesgo | BP7: 0 | CL7: =COUNTIF(AT7:BH7,"*OK*") -> 0 | CN7: =COUNTIF(AT7:BH7,"*OP*") -> 0
A8: 21115 | B8: IPG970717QU9 | C8: =AD8 -> 3750.85 | D8: =COUNTIF(AT8:BH8,"*OK*") -> 1 | E8: Raúl Campos | F8: ABSORMEX CMPC TISSUE | G8: SOFTYS | H8: =IF(LEN(TRIM($G8&""))=0, $C8, SUMIF($G$3:$G$561, TRIM($G8), $C$3:$C$561)) -> 6088.85 | I8: ENTERPRISE | K8: FDP | L8: =HYPERLINK("https://crm.zoho.com/crm/org685875245/tab/Accounts/3525045000374250631","https://crm.zoho.com/crm/org685875245/tab/Accounts/3525045000374250631") -> https://crm.zoho.com/crm/org685875245/tab/Accounts/3525045000374250631 | M8: Mantener | O8: Jessica | P8: 5534151683 | Q8: jessica.romero@softys.com | U8: - | V8: 2906 | W8: 2906 | X8: 3706 | Y8: 2906 | Z8: 2906 | AA8: 3750.85 | AB8: 3750.85 | AC8: 3750.85 | AD8: 3750.85 | AE8: 3242 | AF8: 2000 | AI8: Nuevo León | AJ8: Manufactura | AK8: Fabricante mexicano de productos higiénicos como papel tissue, pañales y artículos de incontinencia bajo el grupo CMPC, con plantas en García NL, Altamira Tamps y Cuautitlán EDOMEX. | AN8: 2. Videollamada | AO8: Diario | AY8: OK(032026) | BJ8: =COUNTIF(AT8:BI8,"*OP*") -> 0 | BL8: =(COUNTIF(AT8:AV8,"*OK*")*3) + (COUNTIF(AW8:AY8,"*OK*")*2) + COUNTIF(AZ8:BB8,"*OK*")+COUNTIF(BK8:BK8,"SI")*0.5 -> 2 | BM8: =IF(BL8<0.6,"Demasiado Riesgo",IF(BL8<=5,"Riesgo Medio",IF(BL8<=11,"Riesgo Bajo","Cliente Blindado"))) -> Riesgo Medio | BN8: Ambos | BP8: 0 | CL8: =COUNTIF(AT8:BH8,"*OK*") -> 1 | CN8: =COUNTIF(AT8:BH8,"*OP*") -> 0
A9: 30644 | B9: GJU880623116 | C9: =AD9 -> 3430.4636 | D9: =COUNTIF(AT9:BH9,"*OK*") -> 0 | E9: Raúl Campos | F9: GRUPO JULIO | G9: JULIO | H9: =IF(LEN(TRIM($G9&""))=0, $C9, SUMIF($G$3:$G$561, TRIM($G9), $C$3:$C$561)) -> 4176.8213 | I9: ENTERPRISE | L9: =HYPERLINK("https://crm.zoho.com/crm/org685875245/tab/Accounts/3525045000446689264","https://crm.zoho.com/crm/org685875245/tab/Accounts/3525045000446689264") -> https://crm.zoho.com/crm/org685875245/tab/Accounts/3525045000446689264 | M9: Expandir | O9: Eduardo | P9: 7751341466 | Q9: eduardo_delrioo@proymoda.com | R9: Ver si invitamos, fue al evento anterior | U9: 17. Retail Enterprise | V9: 2436.17 | W9: 2750.35 | X9: 3261.23 | Y9: 3380.57 | Z9: 3430.9087 | AA9: 3436.49 | AB9: 3516.2948 | AC9: 3652.4096 | AD9: 3430.4636 | AE9: 1624 | AF9: 1300 | AI9: CDMX | AJ9: Retail | AK9: Cadena mexicana de moda femenina con más de 40 años, con 107 tiendas propias y presencia en corners de Palacio de Hierro y Liverpool a nivel nacional y en Colombia. | AN9: 2. Videollamada | AS9: SI | BJ9: =COUNTIF(AT9:BI9,"*OP*") -> 0 | BK9: NO | BL9: =(COUNTIF(AT9:AV9,"*OK*")*3) + (COUNTIF(AW9:AY9,"*OK*")*2) + COUNTIF(AZ9:BB9,"*OK*")+COUNTIF(BK9:BK9,"SI")*0.5 -> 0 | BM9: =IF(BL9<0.6,"Demasiado Riesgo",IF(BL9<=5,"Riesgo Medio",IF(BL9<=11,"Riesgo Bajo","Cliente Blindado"))) -> Demasiado Riesgo | BP9: 0 | CL9: =COUNTIF(AT9:BH9,"*OK*") -> 0 | CN9: =COUNTIF(AT9:BH9,"*OP*") -> 0
A10: 21746 | B10: SIT890317V85 | C10: =AD10 -> 2469.2638 | D10: =COUNTIF(AT10:BH10,"*OK*") -> 0 | E10: Raúl Campos | F10: SISTEMAS INTEGRALES PARA EL TRANSPORTE(SINTRA) | H10: =IF(LEN(TRIM($G10&""))=0, $C10, SUMIF($G$3:$G$561, TRIM($G10), $C$3:$C$561)) -> 2469.2638 | I10: ENTERPRISE | L10: =HYPERLINK("https://crm.zoho.com/crm/org685875245/tab/Accounts/3525045000235830157","https://crm.zoho.com/crm/org685875245/tab/Accounts/3525045000235830157") -> https://crm.zoho.com/crm/org685875245/tab/Accounts/3525045000235830157 | M10: Expandir | O10: Joanna | P10: 5574683122 | Q10: joanna.ruiz@sintra.com.mx | R10: Invitado | U10: - | V10: 2248.55 | W10: 2266.22 | X10: 2393.43 | Y10: 2366.17 | Z10: 2521.1147 | AA10: 2517.37 | AB10: 2581.0536 | AC10: 2631.0647 | AD10: 2469.2638 | AE10: 1061 | AF10: 500 | AI10: CDMX | AJ10: Transporte | AK10: Empresa fundada en 1989 especializada en consultoría, ingeniería y mantenimiento de sistemas de transporte masivo (metro, tren ligero) en México y Latinoamérica. | AN10: 4. Whatsapp | AR10: SAP | AS10: SI | BJ10: =COUNTIF(AT10:BI10,"*OP*") -> 0 | BK10: NO | BL10: =(COUNTIF(AT10:AV10,"*OK*")*3) + (COUNTIF(AW10:AY10,"*OK*")*2) + COUNTIF(AZ10:BB10,"*OK*")+COUNTIF(BK10:BK10,"SI")*0.5 -> 0 | BM10: =IF(BL10<0.6,"Demasiado Riesgo",IF(BL10<=5,"Riesgo Medio",IF(BL10<=11,"Riesgo Bajo","Cliente Blindado"))) -> Demasiado Riesgo | BP10: 0 | CL10: =COUNTIF(AT10:BH10,"*OK*") -> 0 | CN10: =COUNTIF(AT10:BH10,"*OP*") -> 0
A11: 20338 | B11: SAT170927Q91 | C11: =AD11 -> 2258.1678 | D11: =COUNTIF(AT11:BH11,"*OK*") -> 0 | E11: Raúl Campos | F11: SERVICIOS ADMINISTRATIVOS TRANSFORMANDO LA EDUCACION DE MEXICO(Innova Schools) | H11: =IF(LEN(TRIM($G11&""))=0, $C11, SUMIF($G$3:$G$561, TRIM($G11), $C$3:$C$561)) -> 2258.1678 | I11: ENTERPRISE | L11: =HYPERLINK("https://crm.zoho.com/crm/org685875245/tab/Accounts/3525045000188435082","https://crm.zoho.com/crm/org685875245/tab/Accounts/3525045000188435082") -> https://crm.zoho.com/crm/org685875245/tab/Accounts/3525045000188435082 | M11: Mantener | N11: Cliente nos comenta que la baja de marcas se debe al periodo vacacional de abril | O11: Jadiel | P11: 7714167383 | Q11: jadiel.ake@innovaschools.edu.mx | R11: Registrado | U11: - | V11: 2241.41 | W11: 2295.53 | X11: 2210.88 | Y11: 2185.94 | Z11: 2239.7269 | AA11: 2191.06 | AB11: 2197.4221 | AC11: 2465.3354 | AD11: 2258.1678 | AE11: 938 | AF11: 500 | AI11: CDMX | AJ11: Educación | AK11: Red de colegios privados Innova Schools en México, con propuesta educativa innovadora orientada a habilidades del siglo XXI. | AN11: 2. Videollamada | AQ11: Sirve para nómina como relaciones laborales | AR11: Compaq | BJ11: =COUNTIF(AT11:BI11,"*OP*") -> 0 | BL11: =(COUNTIF(AT11:AV11,"*OK*")*3) + (COUNTIF(AW11:AY11,"*OK*")*2) + COUNTIF(AZ11:BB11,"*OK*")+COUNTIF(BK11:BK11,"SI")*0.5 -> 0 | BM11: =IF(BL11<0.6,"Demasiado Riesgo",IF(BL11<=5,"Riesgo Medio",IF(BL11<=11,"Riesgo Bajo","Cliente Blindado"))) -> Demasiado Riesgo | BP11: 0 | CL11: =COUNTIF(AT11:BH11,"*OK*") -> 0 | CN11: =COUNTIF(AT11:BH11,"*OP*") -> 0
A12: 28362 | B12: OOM960429832 | C12: =AD12 -> 2140.3863 | D12: =COUNTIF(AT12:BH12,"*OK*") -> 1 | E12: Raúl Campos | F12: OPERADORA OMX | H12: =IF(LEN(TRIM($G12&""))=0, $C12, SUMIF($G$3:$G$561, TRIM($G12), $C$3:$C$561)) -> 2140.3863 | I12: ENTERPRISE | M12: Alcanzar | O12: Jasiel | P12: 1111111111 | Q12: shantal.reyes@officemax.com.mx | R12: Invitar | U12: - | V12: 2635.78 | W12: 2477.12 | X12: 2238.1 | Y12: 2313.69 | Z12: 2169.8897 | AA12: 2173.35 | AB12: 2337.4804 | AC12: 2365.8489 | AD12: 2140.3863 | AE12: 2225 | AF12: 3000 | AI12: CDMX | AJ12: Retail | AK12: Razón social de OfficeMax México, cadena de 93 tiendas especializadas en artículos de oficina, papelería, tecnología y servicios de impresión. | AN12: 4. Whatsapp | AS12: SI | AT12: OP (Q3) | AU12: OP (Q3) | AV12: OK (negociación inicial) | BJ12: =COUNTIF(AT12:BI12,"*OP*") -> 2 | BK12: NO | BL12: =(COUNTIF(AT12:AV12,"*OK*")*3) + (COUNTIF(AW12:AY12,"*OK*")*2) + COUNTIF(AZ12:BB12,"*OK*")+COUNTIF(BK12:BK12,"SI")*0.5 -> 3 | BM12: =IF(BL12<0.6,"Demasiado Riesgo",IF(BL12<=5,"Riesgo Medio",IF(BL12<=11,"Riesgo Bajo","Cliente Blindado"))) -> Riesgo Medio | BP12: 0 | CL12: =COUNTIF(AT12:BH12,"*OK*") -> 1 | CN12: =COUNTIF(AT12:BH12,"*OP*") -> 2
A13: 21115 | B13: PIM810710R32 | C13: =AD13 -> 2338 | D13: =COUNTIF(AT13:BH13,"*OK*") -> 1 | E13: Raúl Campos | F13: PRODUCTOS INTERNACIONALES MABE | G13: SOFTYS | H13: =IF(LEN(TRIM($G13&""))=0, $C13, SUMIF($G$3:$G$561, TRIM($G13), $C$3:$C$561)) -> 6088.85 | I13: ENTERPRISE | K13: FDP | L13: =HYPERLINK("https://crm.zoho.com/crm/org685875245/tab/Accounts/3525045000133599062","https://crm.zoho.com/crm/org685875245/tab/Accounts/3525045000133599062") -> https://crm.zoho.com/crm/org685875245/tab/Accounts/3525045000133599062 | M13: Mantener | O13: Jessica | P13: 5534151683 | Q13: jessica.romero@softys.com | U13: - | V13: 2338 | W13: 2338 | X13: 2338 | Y13: 2338 | Z13: 2338 | AA13: 2338 | AB13: 2338 | AC13: 2338 | AD13: 2338 | AE13: 3242 | AF13: 3000 | AI13: CDMX | AJ13: Manufactura | AK13: Empresa del Grupo SOFTYS (CMPC), fabricante y distribuidora de productos de consumo masivo para el hogar a nivel nacional e internacional. | AN13: 2. Videollamada | AO13: Diario | AS13: SI | AZ13: OK(092025) | BA13: OP | BJ13: =COUNTIF(AT13:BI13,"*OP*") -> 1 | BK13: NO | BL13: =(COUNTIF(AT13:AV13,"*OK*")*3) + (COUNTIF(AW13:AY13,"*OK*")*2) + COUNTIF(AZ13:BB13,"*OK*")+COUNTIF(BK13:BK13,"SI")*0.5 -> 1 | BM13: =IF(BL13<0.6,"Demasiado Riesgo",IF(BL13<=5,"Riesgo Medio",IF(BL13<=11,"Riesgo Bajo","Cliente Blindado"))) -> Riesgo Medio | CL13: =COUNTIF(AT13:BH13,"*OK*") -> 1 | CN13: =COUNTIF(AT13:BH13,"*OP*") -> 1
A14: 31120 | B14: VAL110809NA0 | C14: =AD14 -> 1952.8145 | D14: =COUNTIF(AT14:BH14,"*OK*") -> 2 | E14: Dafne de la Rosa | F14: VALKIPRO | G14: COPERVA | H14: =IF(LEN(TRIM($G14&""))=0, $C14, SUMIF($G$3:$G$561, TRIM($G14), $C$3:$C$561)) -> 1952.8145 | I14: ENTERPRISE | L14: =HYPERLINK("https://crm.zoho.com/crm/org685875245/tab/Accounts/3525045000467366531","https://crm.zoho.com/crm/org685875245/tab/Accounts/3525045000467366531") -> https://crm.zoho.com/crm/org685875245/tab/Accounts/3525045000467366531 | M14: Expandir | N14: Seguimiento a requerimiento solicitado de SI. Fecha de entrega 07 de julio. | O14: Alejandro | P14: 5560455654 | Q14: avalencia@coperva.com | R14: Invitado | U14: - | V14: 1653.11 | W14: 2016.69 | X14: 1954.18 | Y14: 2017.09 | Z14: 2044.2295 | AA14: 2021.82 | AB14: 1399.2923 | AC14: 2076.353 | AD14: 1952.8145 | AE14: 661 | AF14: 636 | AH14: CDMX | AI14: CDMX | AJ14: Outsourcing | AK14: Empresa de outsourcing especializada en servicios de call center y cobranza, opera bajo la marca Coperva atendiendo a instituciones financieras. | AL14: Call Center Cobranza | AS14: SI | AY14: OK(022026) | AZ14: OK(112025) | BJ14: =COUNTIF(AT14:BI14,"*OP*") -> 0 | BK14: NO | BL14: =(COUNTIF(AT14:AV14,"*OK*")*3) + (COUNTIF(AW14:AY14,"*OK*")*2) + COUNTIF(AZ14:BB14,"*OK*")+COUNTIF(BK14:BK14,"SI")*0.5 -> 3 | BM14: =IF(BL14<0.6,"Demasiado Riesgo",IF(BL14<=5,"Riesgo Medio",IF(BL14<=11,"Riesgo Bajo","Cliente Blindado"))) -> Riesgo Medio | BO14: cobrar a base datos | BP14: 0 | BQ14: Llamada | CL14: =COUNTIF(AT14:BH14,"*OK*") -> 2 | CN14: =COUNTIF(AT14:BH14,"*OP*") -> 0
A15: 3115 | B15: LAP9408085S6 | C15: =AD15 -> 1912.2517 | D15: =COUNTIF(AT15:BH15,"*OK*") -> 0 | E15: Raúl Campos | F15: LAPI | H15: =IF(LEN(TRIM($G15&""))=0, $C15, SUMIF($G$3:$G$561, TRIM($G15), $C$3:$C$561)) -> 1912.2517 | I15: ENTERPRISE | L15: =HYPERLINK("https://crm.zoho.com/crm/org685875245/tab/Accounts/3525045000152712240","https://crm.zoho.com/crm/org685875245/tab/Accounts/3525045000152712240") -> https://crm.zoho.com/crm/org685875245/tab/Accounts/3525045000152712240 | M15: Mantener | N15: Presupuesto anual ir mapeando oportunidad para tenerla lista al final del Q3 Sesión semana del 25 de mayo, se está consiguiendo reu | O15: Alejandro | P15: 5631826460 | Q15: alejandro.martinez@grupolapi.com.mx | R15: Invitado | U15: 15. Planta Productiva | V15: 2009.84 | W15: 2008 | X15: 1913.59 | Y15: 1975.19 | Z15: 2001.7678 | AA15: 1979.82 | AB15: 1996.5198 | AC15: 2033.224 | AD15: 1912.2517 | AE15: 1002 | AF15: 1177 | AI15: CDMX | AJ15: Salud | AK15: Laboratorio médico mexicano con más de 30 años de experiencia, ofrece análisis clínicos, estudios de gabinete e imagenología para empresas e instituciones públicas y privadas. | AN15: 4. Whatsapp | BJ15: =COUNTIF(AT15:BI15,"*OP*") -> 0 | BL15: =(COUNTIF(AT15:AV15,"*OK*")*3) + (COUNTIF(AW15:AY15,"*OK*")*2) + COUNTIF(AZ15:BB15,"*OK*")+COUNTIF(BK15:BK15,"SI")*0.5 -> 0 | BM15: =IF(BL15<0.6,"Demasiado Riesgo",IF(BL15<=5,"Riesgo Medio",IF(BL15<=11,"Riesgo Bajo","Cliente Blindado"))) -> Demasiado Riesgo | BP15: 0 | CL15: =COUNTIF(AT15:BH15,"*OK*") -> 0 | CN15: =COUNTIF(AT15:BH15,"*OP*") -> 0
A16: 31781 | B16: GFS230216MD6 | C16: =AD16 -> 1651.2081 | D16: 1 | E16: Dafne de la Rosa | F16: GRUPO FERROCARRILERO DEL SURESTE | G16: GFS | H16: =IF(LEN(TRIM($G16&""))=0, $C16, SUMIF($G$3:$G$561, TRIM($G16), $C$3:$C$561)) -> 1651.2081 | I16: ENTERPRISE | L16: =HYPERLINK("https://crm.zoho.com/crm/org685875245/tab/Accounts/3525045000478422670","https://crm.zoho.com/crm/org685875245/tab/Accounts/3525045000478422670") -> https://crm.zoho.com/crm/org685875245/tab/Accounts/3525045000478422670 | M16: Expandir | N16: Reu viernes 9am | O16: Adriana | P16: 5219622197821 | Q16: adrianatomas08@gmail.com | R16: No en CDMX | S16: Mapeada en junio, julio, agosto | U16: 3. Construcción | V16: 2193.26 | W16: 2095.65 | X16: 1721.32 | Y16: 1776.73 | Z16: 1831.5447 | AA16: 1806.37 | AB16: 1816.466 | AC16: 1805.3797 | AD16: 1651.2081 | AE16: 822 | AF16: 1260 | AH16: Chiapas | AI16: Chiapas | AJ16: Construcción | AK16: Empresa constructora regional enfocada en obras de infraestructura y proyectos de ingeniería civil en el sureste de México. | AL16: Construcción | AR16: Contpaqi | AS16: SI | AV16: OP (550, puede ser perdido) | AW16: OP | AX16: OP | BJ16: =COUNTIF(AT16:BI16,"*OP*") -> 3 | BL16: =(COUNTIF(AT16:AV16,"*OK*")*3) + (COUNTIF(AW16:AY16,"*OK*")*2) + COUNTIF(AZ16:BB16,"*OK*")+COUNTIF(BK16:BK16,"SI")*0.5 -> 0 | BM16: =IF(BL16<0.6,"Demasiado Riesgo",IF(BL16<=5,"Riesgo Medio",IF(BL16<=11,"Riesgo Bajo","Cliente Blindado"))) -> Demasiado Riesgo | BO16: COBRAR A ISAAC | BP16: 0 | BQ16: Correo y Llamada | CL16: =COUNTIF(AT16:BH16,"*OK*") -> 0 | CN16: =COUNTIF(AT16:BH16,"*OP*") -> 3
A17: 26102 | B17: TFV220408B62 | C17: =AD17 -> 1944.5673 | D17: =COUNTIF(AT17:BH17,"*OK*") -> 1 | E17: Dafne de la Rosa | F17: TAKE FLIGHT VENTURES | G17: BIRDMAN | H17: =IF(LEN(TRIM($G17&""))=0, $C17, SUMIF($G$3:$G$561, TRIM($G17), $C$3:$C$561)) -> 1944.5673 | I17: ENTERPRISE | L17: =HYPERLINK("https://crm.zoho.com/crm/org685875245/tab/Accounts/3525045000344765038","https://crm.zoho.com/crm/org685875245/tab/Accounts/3525045000344765038") -> https://crm.zoho.com/crm/org685875245/tab/Accounts/3525045000344765038 | M17: Mantener | N17: Brinda seguimiento. | O17: Cristo Rodriguez | Q17: c.rodriguez@vidabirdman.com | R17: No en CDMX | S17: Mapeada en agosto | U17: 17. Retail Enterprise | V17: 1244.95 | W17: 1189.61 | X17: 1274.89 | Y17: 1289.62 | Z17: 1283.7946 | AA17: 1467.56 | AB17: 1549.2671 | AC17: 1799.0799 | AD17: 1944.5673 | AE17: 526 | AF17: 150 | AH17: Jalisco | AI17: Jalisco | AJ17: Agrícola | AK17: Empresa de agricultura tecnificada e innovación agropecuaria con operaciones en Jalisco, enfocada en sistemas de cultivo y producción de alimentos. | AL17: Planta Productiva | AS17: SI | AZ17: OK(062025) | BJ17: =COUNTIF(AT17:BI17,"*OP*") -> 0 | BK17: SI | BL17: =(COUNTIF(AT17:AV17,"*OK*")*3) + (COUNTIF(AW17:AY17,"*OK*")*2) + COUNTIF(AZ17:BB17,"*OK*")+COUNTIF(BK17:BK17,"SI")*0.5 -> 1.5 | BM17: =IF(BL17<0.6,"Demasiado Riesgo",IF(BL17<=5,"Riesgo Medio",IF(BL17<=11,"Riesgo Bajo","Cliente Blindado"))) -> Riesgo Medio | BO17: cobro sofia envió correodaf team | BP17: 0 | BQ17: Correo | CL17: =COUNTIF(AT17:BH17,"*OK*") -> 1 | CN17: =COUNTIF(AT17:BH17,"*OP*") -> 0
A18: 26808 | B18: EMS970314UZ7 | C18: =AD18 -> 1620.7506 | D18: =COUNTIF(AT18:BH18,"*OK*") -> 0 | E18: Raúl Campos | F18: EULEN DE SEGURIDAD PRIVADA SA DE CV | G18: EULEN | H18: =IF(LEN(TRIM($G18&""))=0, $C18, SUMIF($G$3:$G$561, TRIM($G18), $C$3:$C$561)) -> 3660.4305 | I18: ENTERPRISE | L18: =HYPERLINK("https://crm.zoho.com/crm/org685875245/tab/Accounts/3525045000269312009","https://crm.zoho.com/crm/org685875245/tab/Accounts/3525045000269312009") -> https://crm.zoho.com/crm/org685875245/tab/Accounts/3525045000269312009 | M18: Expandir | O18: Juan Carlos Espinoza | Q18: jcespinoza@eulen.com | U18: 12. Outsourcing Seguridad | V18: 2001.8 | W18: 1993.95 | X18: 1888.74 | Y18: 1968.47 | Z18: 1954.2222 | AA18: 1945.82 | AB18: 1939.534 | AC18: 1782.8998 | AD18: 1620.7506 | AE18: 3424 | AF18: 3060 | AI18: CDMX | AJ18: Seguridad Privada | AK18: Empresa española EULEN con operaciones en México, proveedora de servicios de seguridad privada, vigilancia y protección para corporativos e industria. | AN18: 1. Reuniones presenciales | AU18: OP (Q3) | AV18: OP (Q3) | AY18: OP (Q4) | BI18: OP | BJ18: =COUNTIF(AT18:BI18,"*OP*") -> 4 | BL18: =(COUNTIF(AT18:AV18,"*OK*")*3) + (COUNTIF(AW18:AY18,"*OK*")*2) + COUNTIF(AZ18:BB18,"*OK*")+COUNTIF(BK18:BK18,"SI")*0.5 -> 0 | BM18: =IF(BL18<0.6,"Demasiado Riesgo",IF(BL18<=5,"Riesgo Medio",IF(BL18<=11,"Riesgo Bajo","Cliente Blindado"))) -> Demasiado Riesgo | BP18: 0 | CL18: =COUNTIF(AT18:BH18,"*OK*") -> 0 | CN18: =COUNTIF(AT18:BH18,"*OP*") -> 3
A19: 37069 | B19: ASU961217L85 | C19: =AD19 -> 1103.7528 | D19: =COUNTIF(AX19:BI19,"OK") -> 0 | E19: Raúl Campos | F19: AFORE SURA | H19: =IF(LEN(TRIM($G19&""))=0, $C19, SUMIF($G$3:$G$561, TRIM($G19), $C$3:$C$561)) -> 1103.7528 | I19: ENTERPRISE | O19: María | P19: 5533971794 | Q19: maria.gudino@suramexico.com | R19: Invitado | T19: SI | Z19: 1019.0818 | AA19: 1007.91 | AB19: 1016.4101 | AC19: 1727.5069 | AD19: 1103.7528 | AE19: 241 | AW19: OP (Q3) | AX19: OP (Q3) | BJ19: =COUNTIF(AT19:BI19,"*OP*") -> 2 | BL19: =(COUNTIF(AT19:AV19,"*OK*")*3) + (COUNTIF(AW19:AY19,"*OK*")*2) + COUNTIF(AZ19:BB19,"*OK*")+COUNTIF(BK19:BK19,"SI")*0.5 -> 0 | BM19: =IF(BL19<0.6,"Demasiado Riesgo",IF(BL19<=5,"Riesgo Medio",IF(BL19<=11,"Riesgo Bajo","Cliente Blindado"))) -> Demasiado Riesgo | BP19: 0 | CL19: =COUNTIF(AT19:BH19,"*OK*") -> 0 | CN19: =COUNTIF(AT19:BH19,"*OP*") -> 2
A20: 32725 | B20: IDI910119FX2 | C20: =AD20 -> 1779.8013 | D20: =COUNTIF(AT20:BH20,"*OK*") -> 1 | E20: Dafne de la Rosa | F20: IMPULSORA DE DESARROLLO INTEGRAL (Idinsa) | G20: IDINSA | H20: =IF(LEN(TRIM($G20&""))=0, $C20, SUMIF($G$3:$G$561, TRIM($G20), $C$3:$C$561)) -> 1779.8013 | I20: ENTERPRISE | L20: =HYPERLINK("https://crm.zoho.com/crm/org685875245/tab/Accounts/3525045000416193121","https://crm.zoho.com/crm/org685875245/tab/Accounts/3525045000416193121") -> https://crm.zoho.com/crm/org685875245/tab/Accounts/3525045000416193121 | M20: Expandir | N20: Seguimiento a proyecto terminado Tlalpan | O20: Benjamin | P20: 5546087437 | Q20: bmondragon@grupoidinsa.com | U20: - | V20: 1621.79 | W20: 1899.63 | X20: 2064.25 | Y20: 2613.52 | Z20: 2817.7265 | AA20: 3838.96 | AB20: 2439.1536 | AC20: 1725.1598 | AD20: 1779.8013 | AE20: 2147 | AF20: 3000 | AH20: CDMX | AI20: CDMX | AJ20: Construcción | AK20: Empresa constructora e inmobiliaria (IDINSA) con operaciones en CDMX, especializada en desarrollo de proyectos de infraestructura y edificación. | AL20: Construcción | AR20: Contpaqi | AS20: SI | AX20: OK (Q2) | BJ20: =COUNTIF(AT20:BI20,"*OP*") -> 0 | BL20: =(COUNTIF(AT20:AV20,"*OK*")*3) + (COUNTIF(AW20:AY20,"*OK*")*2) + COUNTIF(AZ20:BB20,"*OK*")+COUNTIF(BK20:BK20,"SI")*0.5 -> 2 | BM20: =IF(BL20<0.6,"Demasiado Riesgo",IF(BL20<=5,"Riesgo Medio",IF(BL20<=11,"Riesgo Bajo","Cliente Blindado"))) -> Riesgo Medio | BO20: COBRAR A EDGAR | BP20: 0 | BQ20: Llamada | CL20: =COUNTIF(AT20:BH20,"*OK*") -> 1 | CN20: =COUNTIF(AT20:BH20,"*OP*") -> 0
A21: 21102 | B21: FME870213IRA | C21: =AD21 -> 1610.3477 | D21: =COUNTIF(AT21:BH21,"*OK*") -> 0 | E21: Raúl Campos | F21: FRUEHAUF DE MEXICO | H21: =IF(LEN(TRIM($G21&""))=0, $C21, SUMIF($G$3:$G$561, TRIM($G21), $C$3:$C$561)) -> 1610.3477 | I21: ENTERPRISE | L21: =HYPERLINK("https://crm.zoho.com/crm/org685875245/tab/Accounts/3525045000199863226","https://crm.zoho.com/crm/org685875245/tab/Accounts/3525045000199863226") -> https://crm.zoho.com/crm/org685875245/tab/Accounts/3525045000199863226 | M21: Mantener | O21: Miriam Vega Vega granados | P21: +525512482560 | Q21: mvega@fruehauf.mx | U21: 15. Planta Productiva | V21: 1627.97 | W21: 1653.86 | X21: 1582.48 | Y21: 1628.98 | Z21: 1660.2541 | AA21: 1633.05 | AB21: 1662.5564 | AC21: 1701.7468 | AD21: 1610.3477 | AE21: 708 | AF21: 800 | AI21: Estado de México | AJ21: Manufactura | AK21: Líder en fabricación de remolques y semirremolques en México con más de 100 años de historia, con planta en Coacalco EDOMEX. Parte del Grupo Fultra. | AN21: 4. Whatsapp | AS21: SI | AT21: OP (hacer demo) | AU21: OP (Q3-SAP) | AV21: NO- usan SAP | AW21: OP (Q3) | BJ21: =COUNTIF(AT21:BI21,"*OP*") -> 3 | BL21: =(COUNTIF(AT21:AV21,"*OK*")*3) + (COUNTIF(AW21:AY21,"*OK*")*2) + COUNTIF(AZ21:BB21,"*OK*")+COUNTIF(BK21:BK21,"SI")*0.5 -> 0 | BM21: =IF(BL21<0.6,"Demasiado Riesgo",IF(BL21<=5,"Riesgo Medio",IF(BL21<=11,"Riesgo Bajo","Cliente Blindado"))) -> Demasiado Riesgo | BN21: Ambos | BP21: 0 | CL21: =COUNTIF(AT21:BH21,"*OK*") -> 0 | CN21: =COUNTIF(AT21:BH21,"*OP*") -> 3
A22: 3946 | B22: FME140425HBA | C22: =AD22 -> 1605.0248 | D22: =COUNTIF(AT22:BH22,"*OK*") -> 0 | E22: Raúl Campos | F22: FLEX-TEC MEXICO | H22: =IF(LEN(TRIM($G22&""))=0, $C22, SUMIF($G$3:$G$561, TRIM($G22), $C$3:$C$561)) -> 1605.0248 | I22: ENTERPRISE | L22: =HYPERLINK("https://crm.zoho.com/crm/org685875245/tab/Accounts/3525045000025417377","https://crm.zoho.com/crm/org685875245/tab/Accounts/3525045000025417377") -> https://crm.zoho.com/crm/org685875245/tab/Accounts/3525045000025417377 | M22: Expandir | N22: Aún no hay reunión | O22: Arturo benjamín Gomez olivo | P22: +528287683234 | Q22: kary_benjamin@hotmail.com | R22: No están en CDMX | U22: - | V22: 1686.99 | W22: 1802.97 | X22: 1790.42 | Y22: 1873.76 | Z22: 1906.7852 | AA22: 1852.39 | AB22: 1641.9793 | AC22: 1627.1865 | AD22: 1605.0248 | AE22: 685 | AF22: 500 | AI22: Nuevo León | AJ22: Manufactura | AK22: Empresa manufacturera especializada en fabricación de mangueras, ductos y componentes flexibles para uso industrial y automotriz. | AN22: 4. Whatsapp | BJ22: =COUNTIF(AT22:BI22,"*OP*") -> 0 | BL22: =(COUNTIF(AT22:AV22,"*OK*")*3) + (COUNTIF(AW22:AY22,"*OK*")*2) + COUNTIF(AZ22:BB22,"*OK*")+COUNTIF(BK22:BK22,"SI")*0.5 -> 0 | BM22: =IF(BL22<0.6,"Demasiado Riesgo",IF(BL22<=5,"Riesgo Medio",IF(BL22<=11,"Riesgo Bajo","Cliente Blindado"))) -> Demasiado Riesgo | CL22: =COUNTIF(AT22:BH22,"*OK*") -> 0
A23: 24950 | B23: TDS240110H51 | C23: =AD23 -> 1387.4172 | D23: =COUNTIF(AT23:BH23,"*OK*") -> 0 | E23: Raúl Campos | F23: TDSYSTEM | H23: =IF(LEN(TRIM($G23&""))=0, $C23, SUMIF($G$3:$G$561, TRIM($G23), $C$3:$C$561)) -> 1387.4172 | I23: ENTERPRISE | M23: Expandir | N23: Es normal pero por renuencia con algunos centros. Pero con lo de la reforma esta situación debe de ir mejorando. Pagan $17 por usuario, pagaron mucho mucho tiempo hasta los 1000 usuarios a pesar de que tenían menos. | O23: Christian | P23: 5559677516 | Q23: christian_soad@hotmail.com | R23: No están en CDMX | U23: - | V23: 1287.8 | W23: 1324.06 | X23: 1313.45 | Y23: 1206.49 | Z23: 1212.9037 | AA23: 1505.86 | AB23: 1407.0711 | AC23: 1525.6515 | AD23: 1387.4172 | AE23: 1366 | AF23: 1500 | AI23: Puebla | AJ23: Tecnología | AK23: T-Systems México, filial de Deutsche Telekom, proveedora de servicios de tecnología de la información, cloud computing, seguridad y SAP para grandes empresas. | AN23: 4. Whatsapp | AQ23: Generar plan atractivo, han visto varios módulos pero no concretan | AS23: SI | BJ23: =COUNTIF(AT23:BI23,"*OP*") -> 0 | BK23: NO | BL23: =(COUNTIF(AT23:AV23,"*OK*")*3) + (COUNTIF(AW23:AY23,"*OK*")*2) + COUNTIF(AZ23:BB23,"*OK*")+COUNTIF(BK23:BK23,"SI")*0.5 -> 0 | BM23: =IF(BL23<0.6,"Demasiado Riesgo",IF(BL23<=5,"Riesgo Medio",IF(BL23<=11,"Riesgo Bajo","Cliente Blindado"))) -> Demasiado Riesgo | BP23: 0 | CL23: =COUNTIF(AT23:BH23,"*OK*") -> 0 | CN23: =COUNTIF(AT23:BH23,"*OP*") -> 0
A24: 33731 | B24: FRU1410043E6 | C24: =AD24 -> 1368.6534 | D24: =COUNTIF(AT24:BH24,"*OK*") -> 0 | E24: Dafne de la Rosa | F24: FRUNATURAL | H24: =IF(LEN(TRIM($G24&""))=0, $C24, SUMIF($G$3:$G$561, TRIM($G24), $C$3:$C$561)) -> 1368.6534 | I24: ENTERPRISE | L24: =HYPERLINK("https://crm.zoho.com/crm/org685875245/tab/Accounts/3525045000505513537","https://crm.zoho.com/crm/org685875245/tab/Accounts/3525045000505513537") -> https://crm.zoho.com/crm/org685875245/tab/Accounts/3525045000505513537 | M24: Expandir | N24: No tienen autorizado presupuesto. | O24: Paulo | P24: 3321541149 | Q24: recursoshumanos@frunatural.com | R24: Invitado | S24: Mapeada en junio | U24: 22. Turismo, Hotelería y Gastronomía | V24: 1218.08 | W24: 1170.61 | X24: 1135.45 | Y24: 1315.65 | Z24: 1446.5878 | AA24: 1419.3 | AB24: 1428.9665 | AC24: 1471.6669 | AD24: 1368.6534 | AE24: 569 | AF24: 250 | AI24: Jalisco | AJ24: Manufactura | AK24: Empresa productora y comercializadora de frutas y verduras procesadas, jugos y productos naturales con operaciones en Jalisco. | AL24: Produccion | AV24: OP | AW24: NO - turnos fijos | BJ24: =COUNTIF(AT24:BI24,"*OP*") -> 1 | BL24: =(COUNTIF(AT24:AV24,"*OK*")*3) + (COUNTIF(AW24:AY24,"*OK*")*2) + COUNTIF(AZ24:BB24,"*OK*")+COUNTIF(BK24:BK24,"SI")*0.5 -> 0 | BM24: =IF(BL24<0.6,"Demasiado Riesgo",IF(BL24<=5,"Riesgo Medio",IF(BL24<=11,"Riesgo Bajo","Cliente Blindado"))) -> Demasiado Riesgo | BO24: cobro daniela inf en otra base de dat | BP24: 0 | BQ24: Correo y Whats | CL24: =COUNTIF(AT24:BH24,"*OK*") -> 0 | CN24: =COUNTIF(AT24:BH24,"*OP*") -> 1
A25: 17458 | B25: DCM000125IY6 | C25: =AD25 -> 1417.5 | D25: =COUNTIF(AT25:BH25,"*OK*") -> 4 | E25: Raúl Campos | F25: DESPEGAR.COM MEXICO (Bestday) | H25: =IF(LEN(TRIM($G25&""))=0, $C25, SUMIF($G$3:$G$561, TRIM($G25), $C$3:$C$561)) -> 1417.5 | I25: ENTERPRISE | L25: =HYPERLINK("https://crm.zoho.com/crm/org685875245/tab/Accounts/3525045000069562306","https://crm.zoho.com/crm/org685875245/tab/Accounts/3525045000069562306") -> https://crm.zoho.com/crm/org685875245/tab/Accounts/3525045000069562306 | M25: Expandir | O25: Matias | P25: 9981364214 | Q25: matias.corso@despegar.com | R25: Referido best day invitado | U25: - | V25: 1417.5 | W25: 1417.5 | X25: 1417.5 | Y25: 1417.5 | Z25: 1417.5 | AA25: 1417.5 | AB25: 1417.5 | AC25: 1417.5 | AD25: 1417.5 | AE25: 949 | AF25: 800 | AI25: CDMX | AJ25: Turismo y Gastronomía | AK25: Filial mexicana de Despegar.com, la principal agencia de viajes online de Latinoamérica, comercializa vuelos, hoteles y paquetes turísticos. | AN25: 2. Videollamada | AT25: OK(062026) | AV25: OK | AW25: OK(062026) | AX25: OK | BJ25: =COUNTIF(AT25:BI25,"*OP*") -> 0 | BK25: NO | BL25: =(COUNTIF(AT25:AV25,"*OK*")*3) + (COUNTIF(AW25:AY25,"*OK*")*2) + COUNTIF(AZ25:BB25,"*OK*")+COUNTIF(BK25:BK25,"SI")*0.5 -> 10 | BM25: =IF(BL25<0.6,"Demasiado Riesgo",IF(BL25<=5,"Riesgo Medio",IF(BL25<=11,"Riesgo Bajo","Cliente Blindado"))) -> Riesgo Bajo | BP25: 0 | CL25: =COUNTIF(AT25:BH25,"*OK*") -> 4 | CN25: =COUNTIF(AT25:BH25,"*OP*") -> 0
A26: 26081 | B26: AJE010718ET5 | C26: =AD26 -> 1370.9895 | D26: =COUNTIF(AT26:BH26,"*OK*") -> 1 | E26: Raúl Campos | F26: AJEMEX | H26: =IF(LEN(TRIM($G26&""))=0, $C26, SUMIF($G$3:$G$561, TRIM($G26), $C$3:$C$561)) -> 1370.9895 | I26: ENTERPRISE | L26: =HYPERLINK("https://crm.zoho.com/crm/org685875245/tab/Accounts/3525045000316185373","https://crm.zoho.com/crm/org685875245/tab/Accounts/3525045000316185373") -> https://crm.zoho.com/crm/org685875245/tab/Accounts/3525045000316185373 | M26: Expandir | O26: Brigham Lopez | Q26: brigham.lopez@ajemexconsultores.mx | U26: 15. Planta Productiva | V26: 1333.25 | W26: 1406.47 | X26: 1356.38 | Y26: 1365.71 | Z26: 1402.0428 | AA26: 1353.09 | AB26: 1396.1418 | AC26: 1400.4378 | AD26: 1370.9895 | AE26: 943 | AF26: 1500 | AI26: Puebla | AJ26: Manufactura | AK26: Filial mexicana del Grupo AJE, fabricante y distribuidora de bebidas como Big Cola, con planta en Huejotzingo Puebla y distribución nacional. | AN26: 4. Whatsapp | AS26: SI | AW26: OK (Q1) | BB26: OP (Q3) | BI26: OP (Q2) | BJ26: =COUNTIF(AT26:BI26,"*OP*") -> 2 | BK26: NO | BL26: =(COUNTIF(AT26:AV26,"*OK*")*3) + (COUNTIF(AW26:AY26,"*OK*")*2) + COUNTIF(AZ26:BB26,"*OK*")+COUNTIF(BK26:BK26,"SI")*0.5 -> 2 | BM26: =IF(BL26<0.6,"Demasiado Riesgo",IF(BL26<=5,"Riesgo Medio",IF(BL26<=11,"Riesgo Bajo","Cliente Blindado"))) -> Riesgo Medio | BN26: Ambos | BP26: 0 | CL26: =COUNTIF(AT26:BH26,"*OK*") -> 1 | CN26: =COUNTIF(AT26:BH26,"*OP*") -> 1
A27: 38318 | B27: UEE200721NC6 | C27: =AD27 -> 1371.4128 | D27: =COUNTIF(AX27:BI27,"OK") -> 0 | E27: Dafne de la Rosa | F27: UNIVERSIDAD DE EXCELENCIA EDUCATIVA MEXICO (UEEM) | G27: UEEM | H27: =IF(LEN(TRIM($G27&""))=0, $C27, SUMIF($G$3:$G$561, TRIM($G27), $C$3:$C$561)) -> 1371.4128 | I27: ENTERPRISE | L27: =HYPERLINK("https://crm.zoho.com/crm/org685875245/tab/Accounts/3525045000380249726","https://crm.zoho.com/crm/org685875245/tab/Accounts/3525045000380249726") -> https://crm.zoho.com/crm/org685875245/tab/Accounts/3525045000380249726 | O27: Areli | P27: 5555555555 | Q27: coordrecursoshumanos@institutoueem.edu.mx | S27: No pueden ir | T27: SI | U27: 7. Educación | AA27: 1354.16 | AB27: 1368.466 | AC27: 1393.6239 | AD27: 1371.4128 | AE27: 392 | BJ27: =COUNTIF(AT27:BI27,"*OP*") -> 0 | BL27: =(COUNTIF(AT27:AV27,"*OK*")*3) + (COUNTIF(AW27:AY27,"*OK*")*2) + COUNTIF(AZ27:BB27,"*OK*")+COUNTIF(BK27:BK27,"SI")*0.5 -> 0 | BM27: =IF(BL27<0.6,"Demasiado Riesgo",IF(BL27<=5,"Riesgo Medio",IF(BL27<=11,"Riesgo Bajo","Cliente Blindado"))) -> Demasiado Riesgo | BO27: en implementación dar seguiento | BP27: 0 | BQ27: Pendiente | CL27: =COUNTIF(AT27:BH27,"*OK*") -> 0 | CN27: =COUNTIF(AT27:BH27,"*OP*") -> 0
A28: 21541 | B28: PQM140212C74 | C28: =AD28 -> 1276.1038 | D28: =COUNTIF(AT28:BH28,"*OK*") -> 0 | E28: Raúl Campos | F28: PROVEEDORA DE QUIMICOS Y MEDICAMENTOS CARE LAB (DAROVI) | G28: DAROVI | H28: =IF(LEN(TRIM($G28&""))=0, $C28, SUMIF($G$3:$G$561, TRIM($G28), $C$3:$C$561)) -> 2111.8102 | I28: ENTERPRISE | L28: =HYPERLINK("https://crm.zoho.com/crm/org685875245/tab/Accounts/3525045000152361120","https://crm.zoho.com/crm/org685875245/tab/Accounts/3525045000152361120") -> https://crm.zoho.com/crm/org685875245/tab/Accounts/3525045000152361120 | M28: Expandir | N28: Op mapeada | O28: Ruth Ines Loredo leon | P28: +525513333636 | Q28: ruth.loredo@farmacosdarovi.com.mx | U28: - | V28: 1170.52 | W28: 1169.45 | X28: 1114.47 | Y28: 1150.34 | Z28: 2046.1938 | AA28: 1321.19 | AB28: 1332.3384 | AC28: 1356.8323 | AD28: 1276.1038 | AE28: 1099 | AF28: 200 | AI28: CDMX | AJ28: Salud | AK28: Empresa del grupo DAROVI proveedora de químicos, reactivos y medicamentos para el sector salud e industria farmacéutica en México. | AN28: 4. Whatsapp | AQ28: Retomar contacto, admin no contesta mucho. A ella se le puede ofrecer permisos y vacaciones | AV28: OP | AZ28: OP (Q3) | BJ28: =COUNTIF(AT28:BI28,"*OP*") -> 2 | BL28: =(COUNTIF(AT28:AV28,"*OK*")*3) + (COUNTIF(AW28:AY28,"*OK*")*2) + COUNTIF(AZ28:BB28,"*OK*")+COUNTIF(BK28:BK28,"SI")*0.5 -> 0 | BM28: =IF(BL28<0.6,"Demasiado Riesgo",IF(BL28<=5,"Riesgo Medio",IF(BL28<=11,"Riesgo Bajo","Cliente Blindado"))) -> Demasiado Riesgo | CL28: =COUNTIF(AT28:BH28,"*OK*") -> 0
A29: 33503 | B29: GTC1701097U7 | C29: =AD29 -> 916.1148 | D29: =COUNTIF(AT29:BH29,"*OK*") -> 1 | E29: Dafne de la Rosa | F29: GTC TERMO CONTROL | G29: GTC | H29: =IF(LEN(TRIM($G29&""))=0, $C29, SUMIF($G$3:$G$561, TRIM($G29), $C$3:$C$561)) -> 916.1148 | I29: ENTERPRISE | L29: =HYPERLINK("https://crm.zoho.com/crm/org685875245/tab/Accounts/3525045000363350205","https://crm.zoho.com/crm/org685875245/tab/Accounts/3525045000363350205") -> https://crm.zoho.com/crm/org685875245/tab/Accounts/3525045000363350205 | M29: Mantener | N29: Se busca el horario disponible para la demos con SICOSS.* | O29: Aremi | P29: 5218123504160 | Q29: nominas@gtc.com.mx | R29: Invitado | S29: Mapeada en junio | U29: 3. Construcción | V29: 962.87 | W29: 961.98 | X29: 1265.51 | Y29: 1306.25 | Z29: 1323.8242 | AA29: 1552.84 | AB29: 1339.3387 | AC29: 1344.6271 | AD29: 916.1148 | AE29: 428 | AF29: 200 | AH29: CDMX | AI29: CDMX | AJ29: Construcción | AK29: Empresa especializada en sistemas de impermeabilización, aislamiento térmico y control de temperatura para proyectos de construcción industrial y comercial. | AL29: Construcción | AS29: SI | AU29: OP (Q3 - Op con Tada o Sicoss, eligiendo ERP) | AV29: OP (Q3) | AW29: NO - turnos sin mucha rotación | AX29: OK(102025) | BJ29: =COUNTIF(AT29:BI29,"*OP*") -> 2 | BK29: NO | BL29: =(COUNTIF(AT29:AV29,"*OK*")*3) + (COUNTIF(AW29:AY29,"*OK*")*2) + COUNTIF(AZ29:BB29,"*OK*")+COUNTIF(BK29:BK29,"SI")*0.5 -> 2 | BM29: =IF(BL29<0.6,"Demasiado Riesgo",IF(BL29<=5,"Riesgo Medio",IF(BL29<=11,"Riesgo Bajo","Cliente Blindado"))) -> Riesgo Medio | BO29: en base de datos | BP29: 0 | BQ29: Llamada | CL29: =COUNTIF(AT29:BH29,"*OK*") -> 1 | CN29: =COUNTIF(AT29:BH29,"*OP*") -> 2
A30: 34024 | B30: GEA130523698 | C30: =AD30 -> 1235.4305 | D30: =COUNTIF(AT30:BH30,"*OK*") -> 0 | E30: Raúl Campos | F30: GRUPO EMPRESARIAL ARAN (Prestamo Yes) | H30: =IF(LEN(TRIM($G30&""))=0, $C30, SUMIF($G$3:$G$561, TRIM($G30), $C$3:$C$561)) -> 1235.4305 | I30: ENTERPRISE | M30: Alcanzar | O30: Janeth | P30: 8120108953 | Q30: administradorrh@prestamosyes.com | R30: No están en CDMX | U30: 5. Consultoria | V30: 1262.51 | W30: 1310.15 | X30: 1213.82 | Y30: 1280.31 | Z30: 1316.7761 | AA30: 1306.57 | AB30: 1343.1709 | AC30: 1326.6127 | AD30: 1235.4305 | AE30: 329 | AF30: 400 | AI30: CDMX | AJ30: Banca y Finanzas | AK30: Grupo financiero que opera el producto Préstamo Yes, plataforma de préstamos personales y microcréditos para personas y pequeñas empresas en México. | AL30: Banco y Finanzas | AW30: OP (Q2) | BJ30: =COUNTIF(AT30:BI30,"*OP*") -> 1 | BL30: =(COUNTIF(AT30:AV30,"*OK*")*3) + (COUNTIF(AW30:AY30,"*OK*")*2) + COUNTIF(AZ30:BB30,"*OK*")+COUNTIF(BK30:BK30,"SI")*0.5 -> 0 | BM30: =IF(BL30<0.6,"Demasiado Riesgo",IF(BL30<=5,"Riesgo Medio",IF(BL30<=11,"Riesgo Bajo","Cliente Blindado"))) -> Demasiado Riesgo | BP30: 0 | CL30: =COUNTIF(AT30:BH30,"*OK*") -> 0 | CN30: =COUNTIF(AT30:BH30,"*OP*") -> 1
A31: 26808 | B31: EMS970314UZ7 | C31: =AD31 -> 1259.0508 | D31: =COUNTIF(AT31:BH31,"*OK*") -> 0 | E31: Raúl Campos | F31: EULEN MEXICO DE SERVICIOS SA DE CV | G31: EULEN | H31: =IF(LEN(TRIM($G31&""))=0, $C31, SUMIF($G$3:$G$561, TRIM($G31), $C$3:$C$561)) -> 3660.4305 | I31: ENTERPRISE | L31: =HYPERLINK("https://crm.zoho.com/crm/org685875245/tab/Accounts/3525045000269312009","https://crm.zoho.com/crm/org685875245/tab/Accounts/3525045000269312009") -> https://crm.zoho.com/crm/org685875245/tab/Accounts/3525045000269312009 | M31: Expandir | U31: - | V31: 1227.06 | W31: 1269.21 | X31: 1157.99 | Y31: 1184.6 | Z31: 1204.1803 | AA31: 1200.46 | AB31: 1198.6033 | AC31: 1310.7107 | AD31: 1259.0508 | AE31: 3424 | AF31: 3060 | AI31: CDMX | AJ31: Outsourcing | AK31: Filial mexicana del Grupo EULEN España, proveedora de servicios de limpieza, mantenimiento y facility management para grandes corporativos. | AN31: 1. Reuniones presenciales | AW31: OP | BJ31: =COUNTIF(AT31:BI31,"*OP*") -> 1 | BL31: =(COUNTIF(AT31:AV31,"*OK*")*3) + (COUNTIF(AW31:AY31,"*OK*")*2) + COUNTIF(AZ31:BB31,"*OK*")+COUNTIF(BK31:BK31,"SI")*0.5 -> 0 | BM31: =IF(BL31<0.6,"Demasiado Riesgo",IF(BL31<=5,"Riesgo Medio",IF(BL31<=11,"Riesgo Bajo","Cliente Blindado"))) -> Demasiado Riesgo | BP31: 0 | CL31: =COUNTIF(AT31:BH31,"*OK*") -> 0 | CN31: =COUNTIF(AT31:BH31,"*OP*") -> 1
A32: 36114 | B32: ASC951228IM0 | C32: =AD32 -> 1184.4371 | D32: =COUNTIF(AT32:BH32,"*OK*") -> 0 | E32: Dafne de la Rosa | F32: ALMACENADORA SUR SA DE CV ORGANIZACION AUXILIAR DEL CREDITO | H32: =IF(LEN(TRIM($G32&""))=0, $C32, SUMIF($G$3:$G$561, TRIM($G32), $C$3:$C$561)) -> 1184.4371 | I32: ENTERPRISE | L32: =HYPERLINK("https://crm.zoho.com/crm/org685875245/tab/Accounts/3525045000417780328","https://crm.zoho.com/crm/org685875245/tab/Accounts/3525045000417780328") -> https://crm.zoho.com/crm/org685875245/tab/Accounts/3525045000417780328 | O32: David | P32: 5619964263 | Q32: david.rocha@alsur.com.mx | R32: No pueden ir | T32: SI | U32: - | X32: 770.08 | Y32: 806.84 | Z32: 807.9863 | AA32: 885.52 | AB32: 1079.3307 | AC32: 1298.7988 | AD32: 1184.4371 | AE32: 490 | AF32: 500 | AI32: CDMX | AJ32: Logística | AK32: Organización auxiliar del crédito dedicada a servicios de almacenamiento, certificación de inventarios y financiamiento sobre mercancías en depósito. | BJ32: =COUNTIF(AT32:BI32,"*OP*") -> 0 | BL32: =(COUNTIF(AT32:AV32,"*OK*")*3) + (COUNTIF(AW32:AY32,"*OK*")*2) + COUNTIF(AZ32:BB32,"*OK*")+COUNTIF(BK32:BK32,"SI")*0.5 -> 0 | BM32: =IF(BL32<0.6,"Demasiado Riesgo",IF(BL32<=5,"Riesgo Medio",IF(BL32<=11,"Riesgo Bajo","Cliente Blindado"))) -> Demasiado Riesgo | BO32: implementación dar seguimiento | BP32: 0 | BQ32: Pendiente | CL32: =COUNTIF(AT32:BH32,"*OK*") -> 0 | CN32: =COUNTIF(AT32:BH32,"*OP*") -> 0
A33: 6588 | B33: SHN571001I66 | C33: =AD33 -> 1211.0927 | D33: =COUNTIF(AT33:BH33,"*OK*") -> 1 | E33: Raúl Campos | F33: SCHETTINO | G33: SCHETTINO | H33: =IF(LEN(TRIM($G33&""))=0, $C33, SUMIF($G$3:$G$561, TRIM($G33), $C$3:$C$561)) -> 2091.1148 | I33: ENTERPRISE | L33: =HYPERLINK("https://crm.zoho.com/crm/org685875245/tab/Accounts/3525045000079373188","https://crm.zoho.com/crm/org685875245/tab/Accounts/3525045000079373188") -> https://crm.zoho.com/crm/org685875245/tab/Accounts/3525045000079373188 | M33: Mantener | O33: Varios | Q33: lespinoza@schettino.com.mx marina.la.0891@gmail.com mlujan@schettino.com.mx josecarmelomendez_@hotmail.com nominas@mexicanadearroz.com.mx denniel.sevilla@gmail.com | R33: No están en CDMX | U33: 15. Planta Productiva | V33: 1803.81 | W33: 1787.44 | X33: 1790.94 | Y33: 1778.47 | Z33: 1512.3312 | AA33: 1823.83 | AB33: 1825.5624 | AC33: 1282.134 | AD33: 1211.0927 | AE33: 858 | AF33: 800 | AI33: CDMX | AJ33: Manufactura | AK33: Grupo alimentario mexicano productor de arroz, salsas y alimentos procesados, con distribución nacional a través de múltiples marcas y plantas de producción. | AN33: 4. Whatsapp | AS33: SI | AT33: OP (Q3) | BD33: OK ($0) | BJ33: =COUNTIF(AT33:BI33,"*OP*") -> 1 | BK33: NO | BL33: =(COUNTIF(AT33:AV33,"*OK*")*3) + (COUNTIF(AW33:AY33,"*OK*")*2) + COUNTIF(AZ33:BB33,"*OK*")+COUNTIF(BK33:BK33,"SI")*0.5 -> 0 | BM33: =IF(BL33<0.6,"Demasiado Riesgo",IF(BL33<=5,"Riesgo Medio",IF(BL33<=11,"Riesgo Bajo","Cliente Blindado"))) -> Demasiado Riesgo | BP33: 0 | CL33: =COUNTIF(AT33:BH33,"*OK*") -> 1 | CN33: =COUNTIF(AT33:BH33,"*OP*") -> 1
A34: 20005 | B34: OCM050331BC9 | C34: =AD34 -> 1606.2913 | D34: =COUNTIF(AT34:BH34,"*OK*") -> 1 | E34: Raúl Campos | F34: CONCESIONARIA MEXIQUENSE | G34: ALEATICA | H34: =IF(LEN(TRIM($G34&""))=0, $C34, SUMIF($G$3:$G$561, TRIM($G34), $C$3:$C$561)) -> 4240.7286 | I34: ENTERPRISE | K34: FDP | M34: Mantener | N34: Tienen Formas de Pago y Personalizaciones | O34: Monica | P34: 5560790550 | Q34: monica.espino@aleatica.com | R34: Registrado | U34: - | V34: i | W34: 1242.47 | X34: 1190.68 | Y34: 1226.73 | Z34: 1233.9902 | AA34: 1231.89 | AB34: 1239.9742 | AC34: 1281.5472 | AD34: 1606.2913 | AE34: 1417 | AF34: 500 | AI34: Estado de México | AJ34: Transporte | AK34: Empresa concesionaria del Grupo Aleatica que opera la autopista Circuito Exterior Mexiquense, red vial de peaje en el Estado de México. | AN34: 2. Videollamada | AY34: OK(102025) | BJ34: =COUNTIF(AT34:BI34,"*OP*") -> 0 | BL34: =(COUNTIF(AT34:AV34,"*OK*")*3) + (COUNTIF(AW34:AY34,"*OK*")*2) + COUNTIF(AZ34:BB34,"*OK*")+COUNTIF(BK34:BK34,"SI")*0.5 -> 2 | BM34: =IF(BL34<0.6,"Demasiado Riesgo",IF(BL34<=5,"Riesgo Medio",IF(BL34<=11,"Riesgo Bajo","Cliente Blindado"))) -> Riesgo Medio | BP34: 0 | CL34: =COUNTIF(AT34:BH34,"*OK*") -> 1 | CN34: =COUNTIF(AT34:BH34,"*OP*") -> 0
A35: 22501 | B35: PLQ9002286Q6 | C35: =AD35 -> 1401.5552 | D35: =COUNTIF(AT35:BH35,"*OK*") -> 2 | E35: Dafne de la Rosa | F35: PRODUCTOS LACTEOS LA QUINTA | H35: =IF(LEN(TRIM($G35&""))=0, $C35, SUMIF($G$3:$G$561, TRIM($G35), $C$3:$C$561)) -> 1401.5552 | I35: ENTERPRISE | L35: =HYPERLINK("https://crm.zoho.com/crm/org685875245/tab/Accounts/3525045000240910580","https://crm.zoho.com/crm/org685875245/tab/Accounts/3525045000240910580") -> https://crm.zoho.com/crm/org685875245/tab/Accounts/3525045000240910580 | M35: Mantener | N35: Solicito un equipo mas. | O35: Victor daniel Alvarado reyes | P35: +524423919373 | Q35: valvarado@lacteoslaquinta.com.mx | U35: 15. Planta Productiva | V35: 1167.9 | W35: 1166.83 | X35: 1156.68 | Y35: 1205.44 | Z35: 1250.8895 | AA35: 1248.74 | AB35: 1128.0958 | AC35: 1252.7348 | AD35: 1401.5552 | AE35: 489 | AF35: 200 | AH35: Queretaro | AI35: Querétaro | AJ35: Manufactura | AK35: Empresa productora de lácteos como leche, quesos y derivados en Querétaro, con distribución regional en el Bajío y zona centro de México. | AL35: Planta Productiva | AS35: SI | AV35: OK(092024) | AX35: OK(092024) | BJ35: =COUNTIF(AT35:BI35,"*OP*") -> 0 | BK35: NO | BL35: =(COUNTIF(AT35:AV35,"*OK*")*3) + (COUNTIF(AW35:AY35,"*OK*")*2) + COUNTIF(AZ35:BB35,"*OK*")+COUNTIF(BK35:BK35,"SI")*0.5 -> 5 | BM35: =IF(BL35<0.6,"Demasiado Riesgo",IF(BL35<=5,"Riesgo Medio",IF(BL35<=11,"Riesgo Bajo","Cliente Blindado"))) -> Riesgo Medio | BO35: victor albarado | BP35: 0 | BQ35: Correo y Llamada | CL35: =COUNTIF(AT35:BH35,"*OK*") -> 2 | CN35: =COUNTIF(AT35:BH35,"*OP*") -> 0
A36: 37414 | B36: TER060227LR4 | C36: =AD36 -> 1176.1589 | D36: =COUNTIF(AX36:BI36,"OK") -> 0 | E36: Raúl Campos | F36: TRANSPORTES ESPECIALIZADOS RUGA | H36: =IF(LEN(TRIM($G36&""))=0, $C36, SUMIF($G$3:$G$561, TRIM($G36), $C$3:$C$561)) -> 1176.1589 | I36: ENTERPRISE | L36: =HYPERLINK("https://crm.zoho.com/crm/org685875245/tab/Accounts/3525045000578056486","https://crm.zoho.com/crm/org685875245/tab/Accounts/3525045000578056486") -> https://crm.zoho.com/crm/org685875245/tab/Accounts/3525045000578056486 | O36: Fernanda | P36: +52 1 55 4186 6494 | T36: SI | U36: 16. Logistica | X36: 1718 | Y36: 1755.95 | Z36: 1702.9758 | AA36: 1716.36 | AB36: 1275.6983 | AC36: 1252.6772 | AD36: 1176.1589 | AE36: 598 | AL36: Logística | BJ36: =COUNTIF(AT36:BI36,"*OP*") -> 0 | BL36: =(COUNTIF(AT36:AV36,"*OK*")*3) + (COUNTIF(AW36:AY36,"*OK*")*2) + COUNTIF(AZ36:BB36,"*OK*")+COUNTIF(BK36:BK36,"SI")*0.5 -> 0 | BM36: =IF(BL36<0.6,"Demasiado Riesgo",IF(BL36<=5,"Riesgo Medio",IF(BL36<=11,"Riesgo Bajo","Cliente Blindado"))) -> Demasiado Riesgo | BP36: 0 | CL36: =COUNTIF(AT36:BH36,"*OK*") -> 0 | CN36: =COUNTIF(AT36:BH36,"*OP*") -> 0
A37: 26084 | B37: GSO060706CM5 | C37: =AD37 -> 1232.1274 | D37: =COUNTIF(AT37:BH37,"*OK*") -> 1 | E37: Dafne de la Rosa | F37: GLORY GLOBAL SOLUTIONS MEXICO | H37: =IF(LEN(TRIM($G37&""))=0, $C37, SUMIF($G$3:$G$561, TRIM($G37), $C$3:$C$561)) -> 1232.1274 | I37: ENTERPRISE | L37: =HYPERLINK("https://crm.zoho.com/crm/org685875245/tab/Accounts/3525045000212428171","https://crm.zoho.com/crm/org685875245/tab/Accounts/3525045000212428171") -> https://crm.zoho.com/crm/org685875245/tab/Accounts/3525045000212428171 | M37: Mantener | N37: Se tiene reunion con la TI aignada el 23 de junio para validar reunion con cliente. | O37: Aída Adsali Rojas Sánchez | P37: +525627178422 | Q37: aida.rojas@mx.glory-global.com | R37: Invitado | U37: 20. Servicios | V37: 1089.82 | W37: 1088.82 | X37: 1031.23 | Y37: 1061.12 | Z37: 831.4564 | AA37: 834.69 | AB37: 859.1604 | AC37: 1252.2266 | AD37: 1232.1274 | AE37: 374 | AF37: 324 | AH37: CDMX | AI37: CDMX | AJ37: Tecnología | AK37: Filial mexicana de Glory Global Solutions, empresa japonesa especializada en soluciones de automatización para manejo de efectivo, cajas registradoras y equipos bancarios. | AL37: Servicios | AS37: SI | AU37: OP (ERP) | AX37: OK(052025) | BJ37: =COUNTIF(AT37:BI37,"*OP*") -> 1 | BK37: NO | BL37: =(COUNTIF(AT37:AV37,"*OK*")*3) + (COUNTIF(AW37:AY37,"*OK*")*2) + COUNTIF(AZ37:BB37,"*OK*")+COUNTIF(BK37:BK37,"SI")*0.5 -> 2 | BM37: =IF(BL37<0.6,"Demasiado Riesgo",IF(BL37<=5,"Riesgo Medio",IF(BL37<=11,"Riesgo Bajo","Cliente Blindado"))) -> Riesgo Medio | BO37: base de datos | BP37: 0 | BQ37: correo mensaje | CL37: =COUNTIF(AT37:BH37,"*OK*") -> 1 | CN37: =COUNTIF(AT37:BH37,"*OP*") -> 1
A38: 21150 | B38: ACM040107U93 | C38: =AD38 -> 1250 | D38: =COUNTIF(AT38:BH38,"*OK*") -> 2 | E38: Raúl Campos | F38: ALIMENTOS CENTRALIZADOS DE MEXICO (AxionLog) | H38: =IF(LEN(TRIM($G38&""))=0, $C38, SUMIF($G$3:$G$561, TRIM($G38), $C$3:$C$561)) -> 1250 | I38: ENTERPRISE | L38: =HYPERLINK("https://crm.zoho.com/crm/org685875245/tab/Accounts/3525045000188390027","https://crm.zoho.com/crm/org685875245/tab/Accounts/3525045000188390027") -> https://crm.zoho.com/crm/org685875245/tab/Accounts/3525045000188390027 | M38: Mantener | N38: Se está cerrando anualidad, si incluyen los modulos dentro, aplicar dcto | O38: JIMEN SABRINA SABRINA MIJALOVICH | P38: +525550915700 | Q38: jimena.mijalovich@axionlog.com | R38: Registrado | U38: 16. Logistica | V38: 1359.76 | W38: 1358.51 | X38: 1294.64 | Y38: 1336.32 | Z38: 1288 | AA38: 1250 | AB38: 1250 | AC38: 1250 | AD38: 1250 | AE38: 1285 | AF38: 300 | AI38: CDMX | AJ38: Manufactura | AK38: Empresa dedicada a la producción y distribución centralizada de alimentos procesados y preparados para el sector institucional y de consumo masivo. | AN38: 4. Whatsapp | AR38: SAP | AV38: OK(032025) | AX38: OK(032025) | BJ38: =COUNTIF(AT38:BI38,"*OP*") -> 0 | BL38: =(COUNTIF(AT38:AV38,"*OK*")*3) + (COUNTIF(AW38:AY38,"*OK*")*2) + COUNTIF(AZ38:BB38,"*OK*")+COUNTIF(BK38:BK38,"SI")*0.5 -> 5 | BM38: =IF(BL38<0.6,"Demasiado Riesgo",IF(BL38<=5,"Riesgo Medio",IF(BL38<=11,"Riesgo Bajo","Cliente Blindado"))) -> Riesgo Medio | BP38: 0 | CL38: =COUNTIF(AT38:BH38,"*OK*") -> 2 | CN38: =COUNTIF(AT38:BH38,"*OP*") -> 0
A39: 20103 | B39: CRM191212EV3 | C39: =AD39 -> 1103.5833 | D39: =COUNTIF(AT39:BH39,"*OK*") -> 0 | E39: Raúl Campos | F39: CORPORACION DE RESTAURANTES MAXIMUS | H39: =IF(LEN(TRIM($G39&""))=0, $C39, SUMIF($G$3:$G$561, TRIM($G39), $C$3:$C$561)) -> 1103.5833 | I39: ENTERPRISE | L39: =HYPERLINK("https://crm.zoho.com/crm/org685875245/tab/Accounts/3525045000394740282","https://crm.zoho.com/crm/org685875245/tab/Accounts/3525045000394740282") -> https://crm.zoho.com/crm/org685875245/tab/Accounts/3525045000394740282 | M39: Alcanzar | N39: El contacto es más con la persona de sistemas. | O39: Arturo | P39: 5555555555 | Q39: it@grupomaximus.com.mx | R39: Registrado | U39: - | V39: 1299.95 | W39: 1216.24 | X39: 1172.74 | Y39: 1203.43 | Z39: 1183.857 | AA39: 1174.41 | AB39: 1219.9929 | AC39: 1224.2573 | AD39: 1103.5833 | AE39: 384 | AF39: 600 | AI39: CDMX | AJ39: Turismo y Gastronomía | AK39: Corporativo restaurantero que opera múltiples marcas y conceptos de gastronomía en México, con presencia en centros comerciales y zonas comerciales del país. | AN39: 4. Whatsapp | AT39: OP (Q3) | AV39: OP (Q3) | AW39: OP (Q3) | BA39: OP (Q3) | BJ39: =COUNTIF(AT39:BI39,"*OP*") -> 4 | BL39: =(COUNTIF(AT39:AV39,"*OK*")*3) + (COUNTIF(AW39:AY39,"*OK*")*2) + COUNTIF(AZ39:BB39,"*OK*")+COUNTIF(BK39:BK39,"SI")*0.5 -> 0 | BM39: =IF(BL39<0.6,"Demasiado Riesgo",IF(BL39<=5,"Riesgo Medio",IF(BL39<=11,"Riesgo Bajo","Cliente Blindado"))) -> Demasiado Riesgo | BP39: 0 | CL39: =COUNTIF(AT39:BH39,"*OK*") -> 0 | CN39: =COUNTIF(AT39:BH39,"*OP*") -> 4
A40: 26664 | B40: BAC920106U98 | C40: =AD40 -> 1212.7483 | D40: =COUNTIF(AT40:BH40,"*OK*") -> 0 | E40: Raúl Campos | F40: BIODIST (DICIPA) | H40: =IF(LEN(TRIM($G40&""))=0, $C40, SUMIF($G$3:$G$561, TRIM($G40), $C$3:$C$561)) -> 1212.7483 | I40: ENTERPRISE | L40: =HYPERLINK("https://crm.zoho.com/crm/org685875245/tab/Accounts/3525045000118304484","https://crm.zoho.com/crm/org685875245/tab/Accounts/3525045000118304484") -> https://crm.zoho.com/crm/org685875245/tab/Accounts/3525045000118304484 | M40: Mantener | O40: Karla | P40: 5550932000 | Q40: samantha.macias@dicipa.com.mx | R40: Registrado | U40: - | V40: 1092.5 | W40: 1104.54 | X40: 1079.95 | Y40: 1118.99 | Z40: 1158.5989 | AA40: 1154.47 | AB40: 1193.0142 | AC40: 1222.8683 | AD40: 1212.7483 | AE40: 1110 | AF40: 200 | AI40: CDMX | AJ40: Salud | AK40: Distribuidora farmacéutica del grupo DICIPA, especializada en distribución de medicamentos y productos biotecnológicos para el sector salud. | AN40: 2. Videollamada | AS40: SI | BJ40: =COUNTIF(AT40:BI40,"*OP*") -> 0 | BK40: NO | BL40: =(COUNTIF(AT40:AV40,"*OK*")*3) + (COUNTIF(AW40:AY40,"*OK*")*2) + COUNTIF(AZ40:BB40,"*OK*")+COUNTIF(BK40:BK40,"SI")*0.5 -> 0 | BM40: =IF(BL40<0.6,"Demasiado Riesgo",IF(BL40<=5,"Riesgo Medio",IF(BL40<=11,"Riesgo Bajo","Cliente Blindado"))) -> Demasiado Riesgo | BP40: 0 | CL40: =COUNTIF(AT40:BH40,"*OK*") -> 0 | CN40: =COUNTIF(AT40:BH40,"*OP*") -> 0
...

Sheet Hoja1
G2: CAFES DE ESPECIALIDAD DE CHIAPAS
G3: FORSAC MEXICO
G4: AGROFORESTAL DEL VALLE DE NEJAPA
G5: GRUPO CONVERSE DE MEXICO
G6: SISTEMAS INTEGRALES PARA EL TRANSPORTE
G7: CESEHSA PRODUCTS
G8: SOCIEDAD INDUSTRIAL EQUIPOS Y SERVICIOS
G9: AJEMEX
G10: IDEAL AUTOMOTIVE MEXICO
G11: QUIMICA BLANTEX
G12: TECNOLOGIA SINTEL
G13: NOMINATIVA TECHNOLOGIES
... G16: FRUEHAUF DE MEXICO

Sheet Semáforo
A1: CROSS-SELLING POR SEGMENTO (USD)
A2: Mes | B2: ENTERPRISE | C2: SMB | D2: Sin dato | E2: Total | G2: Q | H2: Total Q | K2: Q1 | L2: Cross | M2: Meta | N2: Churn promedio | O2: Semáforo
A3: Enero | B3: =SUMIFS('Ventas 2026'!$M:$M,'Ventas 2026'!$E:$E,"Cross selling",'Ventas 2026'!$P:$P,"ENTERPRISE",'Ventas 2026'!$C:$C,"Enero") -> 0 | C3: =SUMIFS('Ventas 2026'!$M:$M,'Ventas 2026'!$E:$E,"Cross selling",'Ventas 2026'!$P:$P,"SMB",'Ventas 2026'!$C:$C,"Enero") -> 0 | D3: =SUMIFS('Ventas 2026'!$M:$M,'Ventas 2026'!$E:$E,"Cross selling",'Ventas 2026'!$P:$P,"Sin dato",'Ventas 2026'!$C:$C,"Enero") -> 0 | E3: =B3+C3+D3 -> 0 | G3: Q1 | H3: =SUM(E3:E5) -> 0 | K3: Dafne | L3: =B37+B38+B39 -> 0 | M3: M1 | N3: =AVERAGE(G88:G90) -> 0.0099004552 | O3: Verde
A4: Febrero | B4: =SUMIFS('Ventas 2026'!$M:$M,'Ventas 2026'!$E:$E,"Cross selling",'Ventas 2026'!$P:$P,"ENTERPRISE",'Ventas 2026'!$C:$C,"Febrero") -> 0 | C4: =SUMIFS('Ventas 2026'!$M:$M,'Ventas 2026'!$E:$E,"Cross selling",'Ventas 2026'!$P:$P,"SMB",'Ventas 2026'!$C:$C,"Febrero") -> 0 | D4: =SUMIFS('Ventas 2026'!$M:$M,'Ventas 2026'!$E:$E,"Cross selling",'Ventas 2026'!$P:$P,"Sin dato",'Ventas 2026'!$C:$C,"Febrero") -> 0 | E4: =B4+C4+D4 -> 0 | G4: Q2 | H4: =SUM(E6:E8) -> 0 | K4: Raúl | L4: =D37+D38+D39 -> 0 | M4: M2 | N4: =AVERAGE(K88:K90) -> 0.0050548042 | O4: Verde
A5: Marzo | B5: =SUMIFS('Ventas 2026'!$M:$M,'Ventas 2026'!$E:$E,"Cross selling",'Ventas 2026'!$P:$P,"ENTERPRISE",'Ventas 2026'!$C:$C,"Marzo") -> 0 | C5: =SUMIFS('Ventas 2026'!$M:$M,'Ventas 2026'!$E:$E,"Cross selling",'Ventas 2026'!$P:$P,"SMB",'Ventas 2026'!$C:$C,"Marzo") -> 0 | D5: =SUMIFS('Ventas 2026'!$M:$M,'Ventas 2026'!$E:$E,"Cross selling",'Ventas 2026'!$P:$P,"Sin dato",'Ventas 2026'!$C:$C,"Marzo") -> 0 | E5: =B5+C5+D5 -> 0 | G5: Q3 | H5: =SUM(E9:E11) -> 0 | K5: Karla | L5: =SUM(C37:C39) -> 0 | M5: No llega | N5: =AVERAGE(I88:I90) -> 0.010611344 | O5: Café
A6: Abril | B6: =SUMIFS('Ventas 2026'!$M:$M,'Ventas 2026'!$E:$E,"Cross selling",'Ventas 2026'!$P:$P,"ENTERPRISE",'Ventas 2026'!$C:$C,"Abril") -> 0 | C6: =SUMIFS('Ventas 2026'!$M:$M,'Ventas 2026'!$E:$E,"Cross selling",'Ventas 2026'!$P:$P,"SMB",'Ventas 2026'!$C:$C,"Abril") -> 0 | D6: =SUMIFS('Ventas 2026'!$M:$M,'Ventas 2026'!$E:$E,"Cross selling",'Ventas 2026'!$P:$P,"Sin dato",'Ventas 2026'!$C:$C,"Abril") -> 0 | E6: =B6+C6+D6 -> 0 | G6: Q4 | H6: =SUM(E12:E14) -> 0
A7: Mayo | B7: =SUMIFS('Ventas 2026'!$M:$M,'Ventas 2026'!$E:$E,"Cross selling",'Ventas 2026'!$P:$P,"ENTERPRISE",'Ventas 2026'!$C:$C,"Mayo") -> 0 | C7: =SUMIFS('Ventas 2026'!$M:$M,'Ventas 2026'!$E:$E,"Cross selling",'Ventas 2026'!$P:$P,"SMB",'Ventas 2026'!$C:$C,"Mayo") -> 0 | D7: =SUMIFS('Ventas 2026'!$M:$M,'Ventas 2026'!$E:$E,"Cross selling",'Ventas 2026'!$P:$P,"Sin dato",'Ventas 2026'!$C:$C,"Mayo") -> 0 | E7: =B7+C7+D7 -> 0
A8: Junio | B8: =SUMIFS('Ventas 2026'!$M:$M,'Ventas 2026'!$E:$E,"Cross selling",'Ventas 2026'!$P:$P,"ENTERPRISE",'Ventas 2026'!$C:$C,"Junio") -> 0 | C8: =SUMIFS('Ventas 2026'!$M:$M,'Ventas 2026'!$E:$E,"Cross selling",'Ventas 2026'!$P:$P,"SMB",'Ventas 2026'!$C:$C,"Junio") -> 0 | D8: =SUMIFS('Ventas 2026'!$M:$M,'Ventas 2026'!$E:$E,"Cross selling",'Ventas 2026'!$P:$P,"Sin dato",'Ventas 2026'!$C:$C,"Junio") -> 0 | E8: =B8+C8+D8 -> 0 | L8: (Junio aun no se cierra)
A9: Julio | B9: =SUMIFS('Ventas 2026'!$M:$M,'Ventas 2026'!$E:$E,"Cross selling",'Ventas 2026'!$P:$P,"ENTERPRISE",'Ventas 2026'!$C:$C,"Julio") -> 0 | C9: =SUMIFS('Ventas 2026'!$M:$M,'Ventas 2026'!$E:$E,"Cross selling",'Ventas 2026'!$P:$P,"SMB",'Ventas 2026'!$C:$C,"Julio") -> 0 | D9: =SUMIFS('Ventas 2026'!$M:$M,'Ventas 2026'!$E:$E,"Cross selling",'Ventas 2026'!$P:$P,"Sin dato",'Ventas 2026'!$C:$C,"Julio") -> 0 | E9: =B9+C9+D9 -> 0 | K9: Q2 | L9: Cross | M9: Meta | N9: Churn promedio | O9: Semáforo
